Workbook
Name NativeTimeline_month_date: #N/A
Name Slicer_app_name: #N/A

Sheet data_monthly
A1: month_date | B1: fiscal_year | C1: banks_live | D1: volume_bn | E1: value_lakh_cr | F1: avg_ticket_rs | G1: volume_per_day_mn | H1: mom_pct | I1: yoy_volume_pct | J1: yoy_value_pct
A2: 42583 | B2: FY17 | C2: 21 | D2: 0 | E2: 0 | F2: 343 | G2: 0
A3: 42614 | B3: FY17 | C3: 25 | D3: 0 | E3: 0 | F3: 3627 | G3: 0 | H3: 0
A4: 42644 | B4: FY17 | C4: 26 | D4: 0 | E4: 0 | F4: 4857 | G4: 0 | H4: 11.1
A5: 42675 | B5: FY17 | C5: 30 | D5: 0 | E5: 0.001 | F5: 3464 | G5: 0 | H5: 190
A6: 42705 | B6: FY17 | C6: 35 | D6: 0.002 | E6: 0.007 | F6: 3557 | G6: 0.1 | H6: 586.2
A7: 42736 | B7: FY17 | C7: 36 | D7: 0.004 | E7: 0.017 | F7: 3803 | G7: 0.1 | H7: 124.1
A8: 42767 | B8: FY17 | C8: 44 | D8: 0.004 | E8: 0.019 | F8: 4424 | G8: 0.2 | H8: -1.8
A9: 42795 | B9: FY17 | C9: 44 | D9: 0.006 | E9: 0.024 | F9: 3807 | G9: 0.2 | H9: 45.4
A10: 42826 | B10: FY18 | C10: 48 | D10: 0.007 | E10: 0.023 | F10: 3155 | G10: 0.2 | H10: 13
A11: 42856 | B11: FY18 | C11: 49 | D11: 0.009 | E11: 0.028 | F11: 2988 | G11: 0.3 | H11: 30
A12: 42887 | B12: FY18 | C12: 52 | D12: 0.01 | E12: 0.031 | F12: 2994 | G12: 0.3 | H12: 10.6
A13: 42917 | B13: FY18 | C13: 53 | D13: 0.012 | E13: 0.034 | F13: 2933 | G13: 0.4 | H13: 12.4
A14: 42948 | B14: FY18 | C14: 55 | D14: 0.017 | E14: 0.042 | F14: 2474 | G14: 0.5 | H14: 44.5 | I14: 18566.7 | J14: 134418.4
A15: 42979 | B15: FY18 | C15: 57 | D15: 0.031 | E15: 0.053 | F15: 1719 | G15: 1 | H15: 84.4 | I15: 34322.2 | J15: 16216.8
A16: 43009 | B16: FY18 | C16: 60 | D16: 0.077 | E16: 0.071 | F16: 917 | G16: 2.5 | H16: 148.4 | I16: 76860 | J16: 14431.2
A17: 43040 | B17: FY18 | C17: 61 | D17: 0.105 | E17: 0.097 | F17: 921 | G17: 3.5 | H17: 36.5 | I17: 36113.8 | J17: 9525.1
A18: 43070 | B18: FY18 | C18: 67 | D18: 0.146 | E18: 0.132 | F18: 905 | G18: 4.7 | H18: 38.7 | I18: 7218.6 | J18: 1761
A19: 43101 | B19: FY18 | C19: 71 | D19: 0.152 | E19: 0.156 | F19: 1026 | G19: 4.9 | H19: 4.3 | I19: 3304.3 | J19: 818
A20: 43132 | B20: FY18 | C20: 86 | D20: 0.171 | E20: 0.191 | F20: 1116 | G20: 6.1 | H20: 12.9 | I20: 3813.2 | J20: 887.1
A21: 43160 | B21: FY18 | C21: 91 | D21: 0.178 | E21: 0.242 | F21: 1358 | G21: 5.7 | H21: 3.9 | I21: 2695.1 | J21: 896.8
A22: 43191 | B22: FY19 | C22: 97 | D22: 0.19 | E22: 0.27 | F22: 1422 | G22: 6.3 | H22: 6.8 | I22: 2540 | J22: 1089.7
A23: 43221 | B23: FY19 | C23: 101 | D23: 0.189 | E23: 0.333 | F23: 1757 | G23: 6.1 | H23: -0.3 | I23: 1924.4 | J23: 1090.1
A24: 43252 | B24: FY19 | C24: 110 | D24: 0.246 | E24: 0.408 | F24: 1657 | G24: 8.2 | H24: 30 | I24: 2280.4 | J24: 1217.9
A25: 43282 | B25: FY19 | C25: 114 | D25: 0.274 | E25: 0.518 | F25: 1894 | G25: 8.8 | H25: 11.1 | I25: 2253.8 | J25: 1419.7
... A123: 46266 | B123: FY27 | C123: 756 | D123: 24.068 | E123: 29.374 | F123: 1220 | G123: 802.3 | H123: -1.8 | I123: 22.6 | J123: 18

Sheet data_fy
A1: fiscal_year | B1: months | C1: fy_status | D1: volume_bn | E1: value_lakh_cr | F1: avg_ticket_rs
A2: FY17 | B2: 8 | C2: Partial | D2: 0.018 | E2: 0.07 | F2: 3912
A3: FY18 | B3: 12 | C3: Complete | D3: 0.915 | E3: 1.1 | F3: 1200
A4: FY19 | B4: 12 | C4: Complete | D4: 5.392 | E4: 8.77 | F4: 1627
A5: FY20 | B5: 12 | C5: Complete | D5: 12.519 | E5: 21.32 | F5: 1703
A6: FY21 | B6: 12 | C6: Complete | D6: 22.331 | E6: 41.04 | F6: 1838
A7: FY22 | B7: 12 | C7: Complete | D7: 45.968 | E7: 84.18 | F7: 1831
A8: FY23 | B8: 12 | C8: Complete | D8: 83.751 | E8: 139.21 | F8: 1662
A9: FY24 | B9: 12 | C9: Complete | D9: 131.13 | E9: 199.95 | F9: 1525
A10: FY25 | B10: 12 | C10: Complete | D10: 185.866 | E10: 260.57 | F10: 1402
A11: FY26 | B11: 12 | C11: Complete | D11: 241.617 | E11: 314.23 | F11: 1301
A12: FY27 | B12: 6 | C12: Partial | D12: 140.5 | E12: 176.93 | F12: 1259

Sheet data_apps
A1: month_date | B1: app_name | C1: app_group | D1: volume_mn | E1: value_cr | F1: vol_share_pct | G1: val_share_pct | H1: avg_ticket_rs | I1: vol_rank
A2: 45536 | B2: PhonePe | C2: PhonePe | D2: 7221.22 | E2: 1030871 | F2: 48.01 | G2: 49.95 | H2: 1428 | I2: 1
A3: 45536 | B3: Google Pay | C3: Google Pay | D3: 5625.22 | E3: 746690.05 | F3: 37.4 | G3: 36.18 | H3: 1327 | I3: 2
A4: 45536 | B4: Paytm | C4: Paytm | D4: 1064.62 | E4: 113351.54 | F4: 7.08 | G4: 5.49 | H4: 1065 | I4: 3
A5: 45536 | B5: CRED | C5: Challengers | D5: 140 | E5: 47982.71 | F5: 0.93 | G5: 2.32 | H5: 3427 | I5: 4
A6: 45536 | B6: Navi | C6: Challengers | D6: 120.41 | E6: 6549.1 | F6: 0.8 | G6: 0.32 | H6: 544 | I6: 5
A7: 45536 | B7: Axis Bank Apps | C7: Challengers | D7: 120.38 | E7: 5986.48 | F7: 0.8 | G7: 0.29 | H7: 497 | I7: 6
A8: 45536 | B8: Amazon Pay | C8: Challengers | D8: 70.98 | E8: 7845.04 | F8: 0.47 | G8: 0.38 | H8: 1105 | I8: 7
A9: 45536 | B9: FamApp by Trio | C9: Challengers | D9: 61.05 | E9: 714.29 | F9: 0.41 | G9: 0.03 | H9: 117 | I9: 8
A10: 45536 | B10: ICICI Bank Apps | C10: Challengers | D10: 53.59 | E10: 21076.12 | F10: 0.36 | G10: 1.02 | H10: 3933 | I10: 9
A11: 45536 | B11: WhatsApp | C11: Challengers | D11: 48.75 | E11: 3586.71 | F11: 0.32 | G11: 0.17 | H11: 736 | I11: 10
A12: 45536 | B12: Kotak Mahindra Bank Apps | C12: Challengers | D12: 47.14 | E12: 6413.16 | F12: 0.31 | G12: 0.31 | H12: 1360 | I12: 11
A13: 45536 | B13: HDFC Bank Apps | C13: Challengers | D13: 36.14 | E13: 8997.11 | F13: 0.24 | G13: 0.44 | H13: 2490 | I13: 12
... A2053: 46235 | B2053: LivQuik | C2053: Challengers | D2053: 0.02 | E2053: 3.43 | F2053: 0 | G2053: 0 | H2053: 1715 | I2053: 92

Sheet data_conc
A1: month_date | B1: top2_share_pct | C1: top5_share_pct | D1: hhi
A2: 45536 | B2: 85.4 | C2: 94.2 | D2: 3757
A3: 45566 | B3: 85.1 | C3: 94 | D3: 3723
A4: 45597 | B4: 84.9 | C4: 93.7 | D4: 3712
A5: 45627 | B5: 84.4 | C5: 93.4 | D5: 3676
A6: 45658 | B6: 84.1 | C6: 93.1 | D6: 3647
A7: 45689 | B7: 83.8 | C7: 93 | D7: 3624
A8: 45717 | B8: 83.3 | C8: 92.7 | D8: 3583
A9: 45748 | B9: 83 | C9: 92.7 | D9: 3552
A10: 45778 | B10: 82.6 | C10: 92.6 | D10: 3518
A11: 45809 | B11: 82 | C11: 92.3 | D11: 3480
A12: 45839 | B12: 81.4 | C12: 92 | D12: 3428
A13: 45870 | B13: 81 | C13: 91.9 | D13: 3399
... A25: 46235 | B25: 77.9 | C25: 92.1 | D25: 3215

Sheet data_mix
A1: month_date | B1: txn_type | C1: volume_mn | D1: value_cr | E1: volume_share_pct | F1: value_share_pct | G1: ticket_rs
A2: 45536 | B2: P2P | C2: 5688.87 | D2: 1497941.1 | E2: 37.8 | F2: 72.6 | G2: 2633
A3: 45536 | B3: P2M | C3: 9352.88 | D3: 566053.64 | E3: 62.2 | F3: 27.4 | G3: 605
A4: 45566 | B4: P2P | C4: 6281.79 | D4: 1681873 | E4: 37.9 | F4: 71.6 | G4: 2677
A5: 45566 | B5: P2M | C5: 10303.18 | D5: 667948.46 | E5: 62.1 | F5: 28.4 | G5: 648
A6: 45597 | B6: P2P | C6: 5833.16 | D6: 1556010.8 | E6: 37.7 | F6: 72.2 | G6: 2668
A7: 45597 | B7: P2M | C7: 9648.87 | D7: 599176.63 | E7: 62.3 | F7: 27.8 | G7: 621
A8: 45627 | B8: P2P | C8: 6335.63 | D8: 1692632.5 | E8: 37.9 | F8: 72.8 | G8: 2672
A9: 45627 | B9: P2M | C9: 10394.38 | D9: 632067.37 | E9: 62.1 | F9: 27.2 | G9: 608
A10: 45658 | B10: P2P | C10: 6426.25 | D10: 1703333 | E10: 37.8 | F10: 72.5 | G10: 2651
A11: 45658 | B11: P2M | C11: 10569.75 | D11: 644704.09 | E11: 62.2 | F11: 27.5 | G11: 610
A12: 45689 | B12: P2P | C12: 6039.45 | D12: 1606397.9 | E12: 37.5 | F12: 73.1 | G12: 2660
A13: 45689 | B13: P2M | C13: 10066.74 | D13: 590083.74 | E13: 62.5 | F13: 26.9 | G13: 586
... A49: 46235 | B49: P2M | C49: 15510.01 | D49: 895320.68 | E49: 63.3 | F49: 30 | G49: 577

Sheet data_season
A1: month_no | B1: month_name | C1: avg_mom_per_day_pct | D1: years_used
A2: 1 | B2: Jan | C2: 1.7 | D2: 6
A3: 2 | B3: Feb | C3: 6.3 | D3: 6
A4: 3 | B4: Mar | C4: 4.4 | D4: 6
A5: 4 | B5: Apr | C5: 2.9 | D5: 6
A6: 5 | B6: May | C6: 0.4 | D6: 6
A7: 6 | B7: Jun | C7: 3.9 | D7: 6
A8: 7 | B8: Jul | C8: 3.8 | D8: 6
A9: 8 | B9: Aug | C9: 5.1 | D9: 6
A10: 9 | B10: Sep | C10: 3.7 | D10: 6
A11: 10 | B11: Oct | C11: 5.9 | D11: 5
A12: 11 | B12: Nov | C12: 1.3 | D12: 5
A13: 12 | B13: Dec | C13: 3.9 | D13: 5

Sheet Calc
A1: Latest month | B1: =MAX(tbl_monthly[month_date]) -> 46266 | D1: {=_xlfn.LET(_xlpm.t, _xlfn._xlws.SORT(tbl_monthly[], 1, 1), _xlpm.n, ROWS(_xlpm.t), _xlpm.c, _xlfn.XMATCH("yoy_volume_pct", tbl_monthly[#Headers]), INDEX(_xlpm.t, _xlfn.SEQUENCE(24, 1, _xlpm.n - 23), CHOOSE({1,2}, 1, _xlpm.c)))} -> 45566 | E1: 45.4 | G1: ="Volume ("&TEXT(B1,"mmm-yy")&")"&CHAR(10)&TEXT(B2,"0.0")&" bn" -> Volume (Sep-26) 24.1 bn
A2: Volume (bn) | B2: =_xlfn.XLOOKUP(B1, tbl_monthly[month_date], tbl_monthly[volume_bn]) -> 24.068 | D2: 45597 | E2: 37.8 | G2: ="Value ("&TEXT(B1,"mmm-yy")&")"&CHAR(10)&"₹"&TEXT(B3,"0.0")&" lakh cr" -> Value (Sep-26) ₹29.4 lakh cr
A3: Value (₹ lakh cr) | B3: =_xlfn.XLOOKUP(B1, tbl_monthly[month_date], tbl_monthly[value_lakh_cr]) -> 29.374 | D3: 45627 | E3: 39.2 | G3: ="YoY growth"&CHAR(10)&TEXT(B4,"0.0")&"%" -> YoY growth 22.6%
A4: YoY volume % | B4: =_xlfn.XLOOKUP(B1, tbl_monthly[month_date], tbl_monthly[yoy_volume_pct]) -> 22.6 | D4: 45658 | E4: 39.3 | G4: ="Avg ticket"&CHAR(10)&"₹"&TEXT(B5,"#,##0") -> Avg ticket ₹1,220
A5: Avg ticket (₹) | B5: =_xlfn.XLOOKUP(B1, tbl_monthly[month_date], tbl_monthly[avg_ticket_rs]) -> 1220 | D5: 45689 | E5: 33.1 | G5: ="Top-2 ("&TEXT(B6,"mmm-yy")&")"&CHAR(10)&TEXT(B8,"0.0")&"%" -> Top-2 (Aug-26) 77.9%
A6: Latest app month | B6: =MAX(tbl_apps[month_date]) -> 46235 | D6: 45717 | E6: 36.2 | G6: ="HHI ("&TEXT(B6,"mmm-yy")&")"&CHAR(10)&TEXT(B9,"#,##0") -> HHI (Aug-26) 3,215
A7: PhonePe share % | B7: =SUMIFS(tbl_apps[vol_share_pct], tbl_apps[month_date], B6, tbl_apps[app_name], "PhonePe") -> 45.64 | D7: 45748 | E7: 34.5 | G7: ="Volume CAGR"&CHAR(10)&TEXT(B10,"0.0%") -> Volume CAGR 100.8%
A8: Top-2 share % | B8: =_xlfn.XLOOKUP(B6, tbl_conc[month_date], tbl_conc[top2_share_pct]) -> 77.9 | D8: 45778 | E8: 33.1
A9: HHI | B9: =_xlfn.XLOOKUP(B6, tbl_conc[month_date], tbl_conc[hhi]) -> 3215 | D9: 45809 | E9: 32.5
A10: Volume CAGR (complete FYs) | B10: {=_xlfn.LET(_xlpm.v, _xlfn._xlws.FILTER(tbl_fy[volume_bn], tbl_fy[fy_status]="Complete"), _xlpm.n, ROWS(_xlpm.v) - 1, (INDEX(_xlpm.v, ROWS(_xlpm.v)) / INDEX(_xlpm.v, 1)) ^ (1 / _xlpm.n) - 1)} -> 1.0077669 | D10: 45839 | E10: 34.9
D11: 45870 | E11: 33.7
D12: 45901 | E12: 30.5
D13: 45931 | E13: 24.8
D14: 45962 | E14: 32.2
D15: 45992 | E15: 29.3
D16: 46023 | E16: 27.7
D17: 46054 | E17: 26.6
D18: 46082 | E18: 23.7
D19: 46113 | E19: 24.9
D20: 46143 | E20: 24.2
D21: 46174 | E21: 23.5
D22: 46204 | E22: 21.5
... D24: 46266 | E24: 22.6

Sheet Pivots
A3: Row Labels | B3: Volume (bn) | C3: Value (₹ lakh cr) | V3: Sum of vol_share_pct | W3: Column Labels | AN3: Sum of volume_share_pct | AO3: Column Labels | BA3: Sum of value_share_pct | BB3: Column Labels
A4: 42583 | B4: 0 | C4: 0 | V4: Row Labels | W4: Challengers | X4: Google Pay | Y4: Paytm | Z4: PhonePe | AA4: Grand Total | AN4: Row Labels | AO4: P2M | AP4: P2P | AQ4: Grand Total | BA4: Row Labels | BB4: P2M | BC4: P2P | BD4: Grand Total
A5: 42614 | B5: 0 | C5: 0 | V5: 45536 | W5: 6.23 | X5: 37.4 | Y5: 7.08 | Z5: 48.01 | AA5: 98.72 | AN5: 45536 | AO5: 62.2 | AP5: 37.8 | AQ5: 100 | BA5: 45536 | BB5: 27.4 | BC5: 72.6 | BD5: 100
A6: 42644 | B6: 0 | C6: 0 | V6: 45566 | W6: 6.59 | X6: 37.39 | Y6: 7.02 | Z6: 47.67 | AA6: 98.67 | AN6: 45566 | AO6: 62.1 | AP6: 37.9 | AQ6: 100 | BA6: 45566 | BB6: 28.4 | BC6: 71.6 | BD6: 100
A7: 42675 | B7: 0 | C7: 0.001 | V7: 45597 | W7: 6.81 | X7: 37.07 | Y7: 6.94 | Z7: 47.81 | AA7: 98.63 | AN7: 45597 | AO7: 62.3 | AP7: 37.7 | AQ7: 100 | BA7: 45597 | BB7: 27.8 | BC7: 72.2 | BD7: 100
A8: 42705 | B8: 0.002 | C8: 0.007 | V8: 45627 | W8: 7.24 | X8: 36.7 | Y8: 6.88 | Z8: 47.72 | AA8: 98.54 | AN8: 45627 | AO8: 62.1 | AP8: 37.9 | AQ8: 100 | BA8: 45627 | BB8: 27.2 | BC8: 72.8 | BD8: 100
A9: 42736 | B9: 0.004 | C9: 0.017 | V9: 45658 | W9: 7.62 | X9: 36.38 | Y9: 6.78 | Z9: 47.67 | AA9: 98.45 | AN9: 45658 | AO9: 62.2 | AP9: 37.8 | AQ9: 100 | BA9: 45658 | BB9: 27.5 | BC9: 72.5 | BD9: 100
A10: 42767 | B10: 0.004 | C10: 0.019 | V10: 45689 | W10: 8.03 | X10: 36.24 | Y10: 6.7 | Z10: 47.54 | AA10: 98.51 | AN10: 45689 | AO10: 62.5 | AP10: 37.5 | AQ10: 100 | BA10: 45689 | BB10: 26.9 | BC10: 73.1 | BD10: 100
A11: 42795 | B11: 0.006 | C11: 0.024 | V11: 45717 | W11: 8.5 | X11: 36.04 | Y11: 6.67 | Z11: 47.25 | AA11: 98.46 | AN11: 45717 | AO11: 62.6 | AP11: 37.4 | AQ11: 100 | BA11: 45717 | BB11: 27.1 | BC11: 72.9 | BD11: 100
A12: 42826 | B12: 0.007 | C12: 0.023 | V12: 45748 | W12: 8.59 | X12: 36.26 | Y12: 6.76 | Z12: 46.73 | AA12: 98.34 | AN12: 45748 | AO12: 63.5 | AP12: 36.5 | AQ12: 100 | BA12: 45748 | BB12: 27.7 | BC12: 72.3 | BD12: 100
A13: 42856 | B13: 0.009 | C13: 0.028 | V13: 45778 | W13: 8.99 | X13: 36.09 | Y13: 6.84 | Z13: 46.48 | AA13: 98.4 | AN13: 45778 | AO13: 63.5 | AP13: 36.5 | AQ13: 100 | BA13: 45778 | BB13: 27.7 | BC13: 72.3 | BD13: 100
A14: 42887 | B14: 0.01 | C14: 0.031 | V14: 45809 | W14: 9.43 | X14: 35.56 | Y14: 6.9 | Z14: 46.46 | AA14: 98.35 | AN14: 45809 | AO14: 63.7 | AP14: 36.3 | AQ14: 100 | BA14: 45809 | BB14: 28.4 | BC14: 71.6 | BD14: 100
A15: 42917 | B15: 0.012 | C15: 0.034 | V15: 45839 | W15: 9.8 | X15: 35.56 | Y15: 7.02 | Z15: 45.88 | AA15: 98.26 | AN15: 45839 | AO15: 63.6 | AP15: 36.4 | AQ15: 100 | BA15: 45839 | BB15: 29.3 | BC15: 70.7 | BD15: 100
A16: 42948 | B16: 0.017 | C16: 0.042 | V16: 45870 | W16: 10.15 | X16: 35.3 | Y16: 7.03 | Z16: 45.74 | AA16: 98.22 | AN16: 45870 | AO16: 63.5 | AP16: 36.5 | AQ16: 100 | BA16: 45870 | BB16: 29.1 | BC16: 70.9 | BD16: 100
... A28: 43313 | B28: 0.312 | C28: 0.542 | V28: 46235 | W28: 13.49 | X28: 32.26 | Y28: 8.03 | Z28: 45.64 | AA28: 99.42 | AN28: 46235 | AO28: 63.3 | AP28: 36.7 | AQ28: 100 | BA28: 46235 | BB28: 30 | BC28: 70 | BD28: 100
A29: 43344 | B29: 0.406 | C29: 0.598 | V29: Grand Total | W29: 238.69 | X29: 836.15 | Y29: 175.05 | Z29: 1114.68 | AA29: 2364.57 | AN29: Grand Total | AO29: 1509.3 | AP29: 890.7 | AQ29: 2400 | BA29: Grand Total | BB29: 688 | BC29: 1712 | BD29: 2400
A30: 43374 | B30: 0.482 | C30: 0.75
A31: 43405 | B31: 0.525 | C31: 0.822
A32: 43435 | B32: 0.62 | C32: 1.026
A33: 43466 | B33: 0.673 | C33: 1.099 | V33: month_date | W33: 46235
A34: 43497 | B34: 0.674 | C34: 1.067
A35: 43525 | B35: 0.8 | C35: 1.335 | V35: Row Labels | W35: Sum of vol_share_pct
A36: 43556 | B36: 0.782 | C36: 1.42 | V36: PhonePe | W36: 45.64
A37: 43586 | B37: 0.734 | C37: 1.524 | V37: Google Pay | W37: 32.26
A38: 43617 | B38: 0.755 | C38: 1.466 | V38: Paytm | W38: 8.03
A39: 43647 | B39: 0.822 | C39: 1.464 | V39: Navi | W39: 4.4
A40: 43678 | B40: 0.918 | C40: 1.545 | V40: super.money | W40: 1.72
A41: 43709 | B41: 0.955 | C41: 1.615 | V41: BHIM | W41: 1.04
A42: 43739 | B42: 1.148 | C42: 1.914 | V42: FamApp by Trio | W42: 0.91
A43: 43770 | B43: 1.219 | C43: 1.892 | V43: WhatsApp | W43: 0.75
A44: 43800 | B44: 1.308 | C44: 2.025 | V44: Axis Bank Apps | W44: 0.6
A45: 43831 | B45: 1.305 | C45: 2.162 | V45: CRED | W45: 0.59
A46: 43862 | B46: 1.326 | C46: 2.225 | V46: Grand Total | W46: 95.94
A47: 43891 | B47: 1.247 | C47: 2.065
A48: 43922 | B48: 1 | C48: 1.511
A49: 43952 | B49: 1.235 | C49: 2.184
A50: 43983 | B50: 1.337 | C50: 2.618
A51: 44013 | B51: 1.497 | C51: 2.905
A52: 44044 | B52: 1.619 | C52: 2.983
A53: 44075 | B53: 1.8 | C53: 3.29
...

Sheet Dashboard
B2: =TEXT("India UPI Growth & Market Concentration (Aug 2016 – ","@")&TEXT(Calc!B1,"mmm yyyy")&")" -> India UPI Growth & Market Concentration (Aug 2016 – Sep 2026)
B6: =LEFT(Calc!G1,FIND(CHAR(10),Calc!G1)-1) -> Volume (Sep-26) | M6: =LEFT(Calc!G2,FIND(CHAR(10),Calc!G2)-1) -> Value (Sep-26) | X6: =LEFT(Calc!G7,FIND(CHAR(10),Calc!G7)-1) -> Volume CAGR | AI6: =LEFT(Calc!G3,FIND(CHAR(10),Calc!G3)-1) -> YoY growth | AT6: =LEFT(Calc!G4,FIND(CHAR(10),Calc!G4)-1) -> Avg ticket | BE6: =LEFT(Calc!G5,FIND(CHAR(10),Calc!G5)-1) -> Top-2 (Aug-26) | BP6: =LEFT(Calc!G6,FIND(CHAR(10),Calc!G6)-1) -> HHI (Aug-26)
B7: =MID(Calc!G1,FIND(CHAR(10),Calc!G1)+1,50) -> 24.1 bn | M7: =MID(Calc!G2,FIND(CHAR(10),Calc!G2)+1,50) -> ₹29.4 lakh cr | X7: =MID(Calc!G7,FIND(CHAR(10),Calc!G7)+1,50) -> 100.8% | AI7: =MID(Calc!G3,FIND(CHAR(10),Calc!G3)+1,50) -> 22.6% | AT7: =MID(Calc!G4,FIND(CHAR(10),Calc!G4)+1,50) -> ₹1,220 | BE7: =MID(Calc!G5,FIND(CHAR(10),Calc!G5)+1,50) -> 77.9% | BP7: =MID(Calc!G6,FIND(CHAR(10),Calc!G6)+1,50) -> 3,215
B10: KEY TAKEAWAYS
C13: • UPI grew 264x in 8 years and now adds ~55 bn transactions a year. | AO13: • Top-2 share fell from 85.4% to 77.9% in 2 years; HHI of 3,215 is still highly concentrated.
C14: • YoY growth has cooled to ~22%, expected at this scale. | AO14: • Navi is the top challenger (+1.88 pp share in a year).
C15: • Average ticket fell from ₹1,838 (FY21) to ₹1,301 (FY26): more small everyday payments. | AO15: • P2M is ~63% of transactions but only ~30% of value.
B18: GROWTH
B61: MARKET CONCENTRATION
B100: PAYMENT MIX | P2M VS P2P
B120: Source: NPCI UPI Product & Ecosystem Statistics. Data till Sep 2026 (app and P2P/P2M data till Aug 2026). CAGR uses complete FYs only (FY18–FY26). Refresh: Data → Refresh All.
